Workbook

Sheet Portada

Sheet Atlas y nueva venta
B2: Mes | C2: Alta sin facturar | D2: Cliente nuevo (ha facturado) | E2: Cliente (3 facturas o +) | F2: Total general
B3: Enero | C3: =Datos!AH6 -> 55 | D3: =Datos!AJ6 -> 35 | E3: =Datos!AI6 -> 42 | F3: =SUM(C3:E3) -> 132
C4: - | D4: =Datos!AJ21 -> 239243.04 | E4: =Datos!AI21 -> 4216487.5 | F4: =SUM(C4:E4) -> 4455730.5
B5: Febrero | C5: =Datos!AH7 -> 28 | D5: =Datos!AJ7 -> 23 | E5: =Datos!AI7 -> 28 | F5: =SUM(C5:E5) -> 79
C6: - | D6: =Datos!AJ22 -> 139022.52 | E6: =Datos!AI22 -> 923884.32 | F6: =SUM(C6:E6) -> 1062906.8
B7: Marzo | C7: =Datos!AH8 -> 33 | D7: =Datos!AJ8 -> 24 | E7: =Datos!AI8 -> 37 | F7: =SUM(C7:E7) -> 94
C8: - | D8: =Datos!AJ23 -> 98967.72 | E8: =Datos!AI23 -> 964667.6 | F8: =SUM(C8:E8) -> 1063635.3
B9: Abril | C9: =Datos!AH9 -> 18 | D9: =Datos!AJ9 -> 22 | E9: =Datos!AI9 -> 36 | F9: =SUM(C9:E9) -> 76
C10: - | D10: =Datos!AJ24 -> 43425.609 | E10: =Datos!AI24 -> 1000965.7 | F10: =SUM(C10:E10) -> 1044391.3
B11: Mayo | C11: =Datos!AH10 -> 20 | D11: =Datos!AJ10 -> 26 | E11: =Datos!AI10 -> 31 | F11: =SUM(C11:E11) -> 77
C12: - | D12: =Datos!AJ25 -> 285948.12 | E12: =Datos!AI25 -> 523948.8 | F12: =SUM(C12:E12) -> 809896.92
B13: Junio | C13: =Datos!AH11 -> 27 | D13: =Datos!AJ11 -> 50 | E13: =Datos!AI11 -> 24 | F13: =SUM(C13:E13) -> 101
C14: - | D14: =Datos!AJ26 -> 231706.52 | E14: =Datos!AI26 -> 422584.52 | F14: =SUM(C14:E14) -> 654291.04
B15: Julio | C15: =Datos!AH12 -> 36 | D15: =Datos!AJ12 -> 56 | E15: =Datos!AI12 -> 0 | F15: =SUM(C15:E15) -> 92
C16: - | D16: =Datos!AJ27 -> 251399.84 | E16: =Datos!AI27 -> 0 | F16: =SUM(C16:E16) -> 251399.84 | R16: Han pagado | S16: Enero | T16: Febrero | U16: Marzo | V16: Abril | W16: Mayo | X16: Junio | Y16: Julio | Z16: Total
B17: Agosto | C17: =Datos!AH13 -> 62 | D17: =Datos!AJ13 -> 13 | E17: =Datos!AI13 -> 0 | F17: =SUM(C17:E17) -> 75
C18: - | D18: =Datos!AJ28 -> 24922.6 | E18: =Datos!AI28 -> 0 | F18: =SUM(C18:E18) -> 24922.6
B19: Total altas | C19: =SUM(C3,C5,C7,C9,C11,C13,C15,C17) -> 279 | D19: =SUM(D3,D5,D7,D9,D11,D13,D15,D17) -> 249 | E19: =SUM(E3,E5,E7,E9,E11,E13,E15,E17) -> 198 | F19: =SUM(F3,F5,F7,F9,F11,F13,F15,F17) -> 726 | R19: Cliente nuevo | S19: =IFERROR(Datos!AH36&" - "&TEXT(Datos!AH36/(Datos!AH37+Datos!AH36),"0.0%"),"") -> 13 - 19.7% | T19: =IFERROR(Datos!AI36&" - "&TEXT(Datos!AI36/(Datos!AI37+Datos!AI36),"0.0%"),"") -> 14 - 34.1% | U19: =IFERROR(Datos!AJ36&" - "&TEXT(Datos!AJ36/(Datos!AJ37+Datos!AJ36),"0.0%"),"") -> 21 - 38.9% | V19: =IFERROR(Datos!AK36&" - "&TEXT(Datos!AK36/(Datos!AK37+Datos!AK36),"0.0%"),"") -> 14 - 35.9% | W19: =IFERROR(Datos!AL36&" - "&TEXT(Datos!AL36/(Datos!AL37+Datos!AL36),"0.0%"),"") -> 11 - 52.4% | X19: =IFERROR(Datos!AM36&" - "&TEXT(Datos!AM36/(Datos!AM37+Datos!AM36),"0.0%"),"") -> 14 - 100.0% | Z19: =Datos!AN36 -> 87
B20: % | C20: =C19/F19 -> 0.38429752 | D20: =D19/F19 -> 0.34297521 | E20: =E19/F19 -> 0.27272727 | R20: Cliente | S20: =IFERROR(Datos!AH37&" - "&TEXT(Datos!AH37/(Datos!AH37+Datos!AH36),"0.0%"),"") -> 53 - 80.3% | T20: =IFERROR(Datos!AI37&" - "&TEXT(Datos!AI37/(Datos!AI37+Datos!AI36),"0.0%"),"") -> 27 - 65.9% | U20: =IFERROR(Datos!AJ37&" - "&TEXT(Datos!AJ37/(Datos!AJ37+Datos!AJ36),"0.0%"),"") -> 33 - 61.1% | V20: =IFERROR(Datos!AK37&" - "&TEXT(Datos!AK37/(Datos!AK37+Datos!AK36),"0.0%"),"") -> 25 - 64.1% | W20: =IFERROR(Datos!AL37&" - "&TEXT(Datos!AL37/(Datos!AL37+Datos!AL36),"0.0%"),"") -> 10 - 47.6% | X20: =IFERROR(Datos!AM37&" - "&TEXT(Datos!AM37/(Datos!AM37+Datos!AM36),"0.0%"),"") -> 0 - 0.0% | Z20: =Datos!AN37 -> 148
B21: Total venta | C21: =SUM(C4,C6,C8,C10,C12,C14,C16,C18) -> 0 | D21: =SUM(D4,D6,D8,D10,D12,D14,D16,D18) -> 1314636 | E21: =SUM(E4,E6,E8,E10,E12,E14,E16,E18) -> 8052538.5 | F21: =SUM(F4,F6,F8,F10,F12,F14,F16,F18) -> 9367174.4 | R21: Total | S21: =IFERROR(Datos!AH38,"0.0%") -> 13 | T21: =IFERROR(Datos!AI38,"0.0%") -> 13 | U21: =IFERROR(Datos!AJ38,"0.0%") -> 8 | V21: =IFERROR(Datos!AK38,"0.0%") -> 17 | W21: =IFERROR(Datos!AL38,"0.0%") -> 29 | X21: =IFERROR(Datos!AM38,"0.0%") -> 49 | Y21: =IFERROR(Datos!AN38,"0.0%") -> 129 | Z21: =Datos!AN38 -> 129
R23: Han pagado | S23: Enero | T23: Febrero | U23: Marzo | V23: Abril | W23: Mayo | X23: Junio | Y23: Julio | Z23: Total
R24: Cliente nuevo | S24: =Datos!AH46 -> 0 | T24: =Datos!AI46 -> 0 | U24: =Datos!AJ46 -> 0 | V24: =Datos!AK46 -> 0 | W24: =Datos!AL46 -> 0 | X24: =Datos!AM46 -> 0 | Z24: =SUM(S24:X24) -> 0
R25: Cliente | S25: =Datos!AH47 -> 0 | T25: =Datos!AI47 -> 0 | U25: =Datos!AJ47 -> 0 | V25: =Datos!AK47 -> 0 | W25: =Datos!AL47 -> 0 | X25: =Datos!AM47 -> 0 | Z25: =SUM(S25:X25) -> 0
R26: Total | S26: =SUM(S24:S25) -> 0 | T26: =SUM(T24:T25) -> 0 | U26: =SUM(U24:U25) -> 0 | V26: =SUM(V24:V25) -> 0 | W26: =SUM(W24:W25) -> 0 | X26: =SUM(X24:X25) -> 0 | Z26: =SUM(S26:X26) -> 0
R28: Sin pago | S28: Enero | T28: Febrero | U28: Marzo | V28: Abril | W28: Mayo | X28: Junio | Y28: Julio | Z28: Total
R29: Cliente | S29: =IF(Datos!AH56=0,"",IFERROR(Datos!AH56&" - "&TEXT(Datos!AH56/(Datos!AH56+Datos!AH36),"0.0%"),"")) | T29: =IF(Datos!AI56=0,"",IFERROR(Datos!AI56&" - "&TEXT(Datos!AI56/(Datos!AI56+Datos!AI36),"0.0%"),"")) | U29: =IF(Datos!AJ56=0,"",IFERROR(Datos!AJ56&" - "&TEXT(Datos!AJ56/(Datos!AJ56+Datos!AJ36),"0.0%"),"")) | V29: =IF(Datos!AK56=0,"",IFERROR(Datos!AK56&" - "&TEXT(Datos!AK56/(Datos!AK56+Datos!AK36),"0.0%"),"")) | W29: =IF(Datos!AL56=0,"",IFERROR(Datos!AL56&" - "&TEXT(Datos!AL56/(Datos!AL56+Datos!AL36),"0.0%"),"")) | X29: =IF(Datos!AM56=0,"",IFERROR(Datos!AM56&" - "&TEXT(Datos!AM56/(Datos!AM56+Datos!AM36),"0.0%"),"")) | Z29: =Datos!AN56 -> 0
R30: Cliente nuevo | S30: =IF(Datos!AH57=0,"",IFERROR(Datos!AH57&" - "&TEXT(Datos!AH57/(Datos!AH57+Datos!AH37),"0.0%"),"")) | T30: =IF(Datos!AI57=0,"",IFERROR(Datos!AI57&" - "&TEXT(Datos!AI57/(Datos!AI57+Datos!AI37),"0.0%"),"")) | U30: =IF(Datos!AJ57=0,"",IFERROR(Datos!AJ57&" - "&TEXT(Datos!AJ57/(Datos!AJ57+Datos!AJ37),"0.0%"),"")) | V30: =IF(Datos!AK57=0,"",IFERROR(Datos!AK57&" - "&TEXT(Datos!AK57/(Datos!AK57+Datos!AK37),"0.0%"),"")) | W30: =IF(Datos!AL57=0,"",IFERROR(Datos!AL57&" - "&TEXT(Datos!AL57/(Datos!AL57+Datos!AL37),"0.0%"),"")) | X30: =IF(Datos!AM57=0,"",IFERROR(Datos!AM57&" - "&TEXT(Datos!AM57/(Datos!AM57+Datos!AM37),"0.0%"),"")) | Y30: =IF(Datos!AN57=0,"",IFERROR(Datos!AN57&" - "&TEXT(Datos!AN57/(Datos!AN57+Datos!AN37),"0.0%"),"")) | Z30: =Datos!AN57 -> 0
R31: Total general | S31: =IF(Datos!AH58=0,"",IFERROR(Datos!AH58&" - "&TEXT(Datos!AH58/(Datos!AH58+Datos!AH38),"0.0%"),"")) | T31: =IF(Datos!AI58=0,"",IFERROR(Datos!AI58&" - "&TEXT(Datos!AI58/(Datos!AI58+Datos!AI38),"0.0%"),"")) | U31: =IF(Datos!AJ58=0,"",IFERROR(Datos!AJ58&" - "&TEXT(Datos!AJ58/(Datos!AJ58+Datos!AJ38),"0.0%"),"")) | V31: =IF(Datos!AK58=0,"",IFERROR(Datos!AK58&" - "&TEXT(Datos!AK58/(Datos!AK58+Datos!AK38),"0.0%"),"")) | W31: =IF(Datos!AL58=0,"",IFERROR(Datos!AL58&" - "&TEXT(Datos!AL58/(Datos!AL58+Datos!AL38),"0.0%"),"")) | X31: =IF(Datos!AM58=0,"",IFERROR(Datos!AM58&" - "&TEXT(Datos!AM58/(Datos!AM58+Datos!AM38),"0.0%"),"")) | Y31: =IF(Datos!AN58=0,"",IFERROR(Datos!AN58&" - "&TEXT(Datos!AN58/(Datos!AN58+Datos!AN38),"0.0%"),"")) | Z31: =Datos!AN58 -> 0
R33: Sin pago | S33: Enero | T33: Febrero | U33: Marzo | V33: Abril | W33: Mayo | X33: Junio | Y33: Julio | Z33: Total
R34: Cliente | S34: =Datos!AH65 -> 0 | T34: =Datos!AI65 -> 0 | U34: =Datos!AJ65 -> 0 | V34: =Datos!AK65 -> 0 | W34: =Datos!AL65 -> 0 | X34: =Datos!AM65 -> 0 | Z34: =SUM(S34:X34) -> 0
R35: Cliente nuevo | S35: =Datos!AH66 -> 0 | T35: =Datos!AI66 -> 0 | U35: =Datos!AJ66 -> 0 | V35: =Datos!AK66 -> 0 | W35: =Datos!AL66 -> 0 | X35: =Datos!AM66 -> 0 | Z35: =SUM(S35:X35) -> 0
R36: Total general | S36: =SUM(S34:S35) -> 0 | T36: =SUM(T34:T35) -> 0 | U36: =SUM(U34:U35) -> 0 | V36: =SUM(V34:V35) -> 0 | W36: =SUM(W34:W35) -> 0 | X36: =SUM(X34:X35) -> 0 | Z36: =SUM(S36:X36) -> 0
S41: .

Sheet Altas x ejecutivo
R1: Ejecutivo | S1: (Varios elementos)
H2: Cuenta de Categoría | I2: Categoría
B3: Ejecutivo | C3: Alta sin facturar (%) | D3: Cliente nuevo (%) | E3: Cliente (%) | G3: Región | H3: Ejecutivo | I3: Alta sin facturar | J3: Cliente nuevo | K3: Cliente | L3: Total altas | M3: =IF(L3="",K3,L3) -> Total altas | N3: Facturado | O3: Límite | S3: Altas | W3: % Altas
B4: =IF(H4="","",H4) -> Yareli Flores | C4: =IF(H4="","",I4/IF(M4="",K4,M4)) -> 0.5862069 | D4: =IF(H4="","",J4/IF(M4="",K4,M4)) -> 0.15517241 | E4: =IF(H4="","",K4/IF(M4="",K4,M4)) -> 0.25862069 | G4: =IFERROR(VLOOKUP(H4,Datos!C:D,2,0),"") -> Centro | H4: Yareli Flores | I4: 34 | J4: 9 | K4: 15 | L4: 58 | M4: =IF(H4="","",IF(L4="",K4,L4)) -> 58 | N4: =_xlfn.XLOOKUP(H4,Datos!$AT$3:$AT$30,Datos!$AX$3:$AX$30,"") -> 423867.48 | O4: =$N$4 -> 423867.48 | P4: =IF(AND(N4>=LARGE($N$4:$N$31,5),M4>=LARGE($M$4:$M$31,5)),1,0) -> 1 | R4: Región | S4: sin facturar | T4: Cliente nuevo | U4: Cliente | V4: Suma | W4: sin facturar
B5: =IF(H5="","",H5) -> Ricardo Vidal | C5: =IF(H5="","",I5/IF(M5="",K5,M5)) -> 0.27777778 | D5: =IF(H5="","",J5/IF(M5="",K5,M5)) -> 0.5 | E5: =IF(H5="","",K5/IF(M5="",K5,M5)) -> 0.22222222 | G5: =IFERROR(VLOOKUP(H5,Datos!C:D,2,0),"") -> Magallanes | H5: Ricardo Vidal | I5: 15 | J5: 27 | K5: 12 | L5: 54 | M5: =IF(H5="","",IF(L5="",K5,L5)) -> 54 | N5: =_xlfn.XLOOKUP(H5,Datos!$AT$3:$AT$30,Datos!$AX$3:$AX$30,"") -> 256792.68 | O5: =$N$4 -> 423867.48 | P5: =IF(AND(N5>=LARGE($N$4:$N$31,5),M5>=LARGE($M$4:$M$31,5)),1,0) -> 0 | R5: Norte | S5: 68 | T5: 45 | U5: 65 | V5: 178 | W5: =GETPIVOTDATA("Categoría",$S$5,"Región","NORTE","Categoría","Alta sin facturar")/GETPIVOTDATA("Categoría",$V$5,"Región","NORTE") -> 0.38202247
B6: =IF(H6="","",H6) -> Marcos López | C6: =IF(H6="","",I6/IF(M6="",K6,M6)) -> 0.20930233 | D6: =IF(H6="","",J6/IF(M6="",K6,M6)) -> 0.79069767 | E6: =IF(H6="","",K6/IF(M6="",K6,M6)) -> 0 | G6: =IFERROR(VLOOKUP(H6,Datos!C:D,2,0),"") -> Sur | H6: Marcos López | I6: 9 | J6: 34 | L6: 43 | M6: =IF(H6="","",IF(L6="",K6,L6)) -> 43 | N6: =_xlfn.XLOOKUP(H6,Datos!$AT$3:$AT$30,Datos!$AX$3:$AX$30,"") -> 312603.76 | O6: =$N$4 -> 423867.48 | P6: =IF(AND(N6>=LARGE($N$4:$N$31,5),M6>=LARGE($M$4:$M$31,5)),1,0) -> 0 | R6: Centro | S6: 141 | T6: 75 | U6: 79 | V6: 295 | W6: =GETPIVOTDATA("Categoría",$R$3,"Región","CENTRO","Categoría","Alta sin facturar")/GETPIVOTDATA("Categoría",$R$3,"Región","CENTRO") -> 0.4779661
B7: =IF(H7="","",H7) -> Alfredo Almaráz | C7: =IF(H7="","",I7/IF(M7="",K7,M7)) -> 0.25581395 | D7: =IF(H7="","",J7/IF(M7="",K7,M7)) -> 0.41860465 | E7: =IF(H7="","",K7/IF(M7="",K7,M7)) -> 0.3255814 | G7: =IFERROR(VLOOKUP(H7,Datos!C:D,2,0),"") -> Magallanes | H7: Alfredo Almaráz | I7: 11 | J7: 18 | K7: 14 | L7: 43 | M7: =IF(H7="","",IF(L7="",K7,L7)) -> 43 | N7: =_xlfn.XLOOKUP(H7,Datos!$AT$3:$AT$30,Datos!$AX$3:$AX$30,"") -> 461678.84 | O7: =$N$4 -> 423867.48 | P7: =IF(AND(N7>=LARGE($N$4:$N$31,5),M7>=LARGE($M$4:$M$31,5)),1,0) -> 1 | R7: Sur | S7: 25 | T7: 66 | U7: 28 | V7: 119 | W7: =GETPIVOTDATA("Categoría",$R$3,"Región","SUR","Categoría","Alta sin facturar")/GETPIVOTDATA("Categoría",$R$3,"Región","SUR") -> 0.21008403
B8: =IF(H8="","",H8) -> Miguel Romero | C8: =IF(H8="","",I8/IF(M8="",K8,M8)) -> 0.45238095 | D8: =IF(H8="","",J8/IF(M8="",K8,M8)) -> 0.38095238 | E8: =IF(H8="","",K8/IF(M8="",K8,M8)) -> 0.16666667 | G8: =IFERROR(VLOOKUP(H8,Datos!C:D,2,0),"") -> Centro | H8: Miguel Romero | I8: 19 | J8: 16 | K8: 7 | L8: 42 | M8: =IF(H8="","",IF(L8="",K8,L8)) -> 42 | N8: =_xlfn.XLOOKUP(H8,Datos!$AT$3:$AT$30,Datos!$AX$3:$AX$30,"") | O8: =$N$4 -> 423867.48 | P8: =IF(AND(N8>=LARGE($N$4:$N$31,5),M8>=LARGE($M$4:$M$31,5)),1,0) -> 1 | R8: Magallanes | S8: 36 | T8: 63 | U8: 26 | V8: 125 | W8: =GETPIVOTDATA("Categoría",$R$3,"Región","MAGALLANES","Categoría","Alta sin facturar")/GETPIVOTDATA("Categoría",$R$3,"Región","MAGALLANES") -> 0.288
B9: =IF(H9="","",H9) -> Genaro Castro | C9: =IF(H9="","",I9/IF(M9="",K9,M9)) -> 0.26190476 | D9: =IF(H9="","",J9/IF(M9="",K9,M9)) -> 0.35714286 | E9: =IF(H9="","",K9/IF(M9="",K9,M9)) -> 0.38095238 | G9: =IFERROR(VLOOKUP(H9,Datos!C:D,2,0),"") -> Sur | H9: Genaro Castro | I9: 11 | J9: 15 | K9: 16 | L9: 42 | M9: =IF(H9="","",IF(L9="",K9,L9)) -> 42 | N9: =_xlfn.XLOOKUP(H9,Datos!$AT$3:$AT$30,Datos!$AX$3:$AX$30,"") -> 381845.32 | O9: =$N$4 -> 423867.48 | P9: =IF(AND(N9>=LARGE($N$4:$N$31,5),M9>=LARGE($M$4:$M$31,5)),1,0) -> 0
B10: =IF(H10="","",H10) -> Christian Castellanos | C10: =IF(H10="","",I10/IF(M10="",K10,M10)) -> 0.525 | D10: =IF(H10="","",J10/IF(M10="",K10,M10)) -> 0.1 | E10: =IF(H10="","",K10/IF(M10="",K10,M10)) -> 0.375 | G10: =IFERROR(VLOOKUP(H10,Datos!C:D,2,0),"") -> Norte | H10: Christian Castellanos | I10: 21 | J10: 4 | K10: 15 | L10: 40 | M10: =IF(H10="","",IF(L10="",K10,L10)) -> 40 | N10: =_xlfn.XLOOKUP(H10,Datos!$AT$3:$AT$30,Datos!$AX$3:$AX$30,"") -> 836155.84 | O10: =$N$4 -> 423867.48 | P10: =IF(AND(N10>=LARGE($N$4:$N$31,5),M10>=LARGE($M$4:$M$31,5)),1,0) -> 0 | R10: Mejor facturación
B11: =IF(H11="","",H11) -> Rubí Rodríguez | C11: =IF(H11="","",I11/IF(M11="",K11,M11)) -> 0.3030303 | D11: =IF(H11="","",J11/IF(M11="",K11,M11)) -> 0.36363636 | E11: =IF(H11="","",K11/IF(M11="",K11,M11)) -> 0.33333333 | G11: =IFERROR(VLOOKUP(H11,Datos!C:D,2,0),"") -> Centro | H11: Rubí Rodríguez | I11: 10 | J11: 12 | K11: 11 | L11: 33 | M11: =IF(H11="","",IF(L11="",K11,L11)) -> 33 | N11: =_xlfn.XLOOKUP(H11,Datos!$AT$3:$AT$30,Datos!$AX$3:$AX$30,"") -> 219351.36 | O11: =$N$4 -> 423867.48 | P11: =IF(AND(N11>=LARGE($N$4:$N$31,5),M11>=LARGE($M$4:$M$31,5)),1,0) -> 0 | R11: Más altas
B12: =IF(H12="","",H12) -> Dolores Jiménez | C12: =IF(H12="","",I12/IF(M12="",K12,M12)) -> 0.1875 | D12: =IF(H12="","",J12/IF(M12="",K12,M12)) -> 0.21875 | E12: =IF(H12="","",K12/IF(M12="",K12,M12)) -> 0.59375 | G12: =IFERROR(VLOOKUP(H12,Datos!C:D,2,0),"") -> Norte | H12: Dolores Jiménez | I12: 6 | J12: 7 | K12: 19 | L12: 32 | M12: =IF(H12="","",IF(L12="",K12,L12)) -> 32 | N12: =_xlfn.XLOOKUP(H12,Datos!$AT$3:$AT$30,Datos!$AX$3:$AX$30,"") -> 336259.64 | O12: =$N$4 -> 423867.48 | P12: =IF(AND(N12>=LARGE($N$4:$N$31,5),M12>=LARGE($M$4:$M$31,5)),1,0) -> 0
B13: =IF(H13="","",H13) -> Iván Luna | C13: =IF(H13="","",I13/IF(M13="",K13,M13)) -> 0.41935484 | D13: =IF(H13="","",J13/IF(M13="",K13,M13)) -> 0.32258065 | E13: =IF(H13="","",K13/IF(M13="",K13,M13)) -> 0.25806452 | G13: =IFERROR(VLOOKUP(H13,Datos!C:D,2,0),"") -> Norte | H13: Iván Luna | I13: 13 | J13: 10 | K13: 8 | L13: 31 | M13: =IF(H13="","",IF(L13="",K13,L13)) -> 31 | N13: =_xlfn.XLOOKUP(H13,Datos!$AT$3:$AT$30,Datos!$AX$3:$AX$30,"") -> 2948272.2 | O13: =$N$4 -> 423867.48 | P13: =IF(AND(N13>=LARGE($N$4:$N$31,5),M13>=LARGE($M$4:$M$31,5)),1,0) -> 0
B14: =IF(H14="","",H14) -> Oscar Moreno | C14: =IF(H14="","",I14/IF(M14="",K14,M14)) -> 0.35714286 | D14: =IF(H14="","",J14/IF(M14="",K14,M14)) -> 0.64285714 | E14: =IF(H14="","",K14/IF(M14="",K14,M14)) -> 0 | G14: =IFERROR(VLOOKUP(H14,Datos!C:D,2,0),"") -> Magallanes | H14: Oscar Moreno | I14: 10 | J14: 18 | L14: 28 | M14: =IF(H14="","",IF(L14="",K14,L14)) -> 28 | N14: =_xlfn.XLOOKUP(H14,Datos!$AT$3:$AT$30,Datos!$AX$3:$AX$30,"") -> 99958.36 | O14: =$N$4 -> 423867.48 | P14: =IF(AND(N14>=LARGE($N$4:$N$31,5),M14>=LARGE($M$4:$M$31,5)),1,0) -> 0
B15: =IF(H15="","",H15) -> Diana Tejadilla | C15: =IF(H15="","",I15/IF(M15="",K15,M15)) -> 0.46428571 | D15: =IF(H15="","",J15/IF(M15="",K15,M15)) -> 0.28571429 | E15: =IF(H15="","",K15/IF(M15="",K15,M15)) -> 0.25 | G15: =IFERROR(VLOOKUP(H15,Datos!C:D,2,0),"") -> Centro | H15: Diana Tejadilla | I15: 13 | J15: 8 | K15: 7 | L15: 28 | M15: =IF(H15="","",IF(L15="",K15,L15)) -> 28 | N15: =_xlfn.XLOOKUP(H15,Datos!$AT$3:$AT$30,Datos!$AX$3:$AX$30,"") -> 118622.76 | O15: =$N$4 -> 423867.48 | P15: =IF(AND(N15>=LARGE($N$4:$N$31,5),M15>=LARGE($M$4:$M$31,5)),1,0) -> 0
B16: =IF(H16="","",H16) -> Yuritzi Alejo | C16: =IF(H16="","",I16/IF(M16="",K16,M16)) -> 0.44 | D16: =IF(H16="","",J16/IF(M16="",K16,M16)) -> 0.16 | E16: =IF(H16="","",K16/IF(M16="",K16,M16)) -> 0.4 | G16: =IFERROR(VLOOKUP(H16,Datos!C:D,2,0),"") -> Centro | H16: Yuritzi Alejo | I16: 11 | J16: 4 | K16: 10 | L16: 25 | M16: =IF(H16="","",IF(L16="",K16,L16)) -> 25 | N16: =_xlfn.XLOOKUP(H16,Datos!$AT$3:$AT$30,Datos!$AX$3:$AX$30,"") -> 772279.86 | O16: =$N$4 -> 423867.48 | P16: =IF(AND(N16>=LARGE($N$4:$N$31,5),M16>=LARGE($M$4:$M$31,5)),1,0) -> 0
B17: =IF(H17="","",H17) -> Leonard Lule | C17: =IF(H17="","",I17/IF(M17="",K17,M17)) -> 0.125 | D17: =IF(H17="","",J17/IF(M17="",K17,M17)) -> 0.375 | E17: =IF(H17="","",K17/IF(M17="",K17,M17)) -> 0.5 | G17: =IFERROR(VLOOKUP(H17,Datos!C:D,2,0),"") -> Sur | H17: Leonard Lule | I17: 3 | J17: 9 | K17: 12 | L17: 24 | M17: =IF(H17="","",IF(L17="",K17,L17)) -> 24 | N17: =_xlfn.XLOOKUP(H17,Datos!$AT$3:$AT$30,Datos!$AX$3:$AX$30,"") | O17: =$N$4 -> 423867.48 | P17: =IF(AND(N17>=LARGE($N$4:$N$31,5),M17>=LARGE($M$4:$M$31,5)),1,0) -> 0
B18: =IF(H18="","",H18) -> Yuriana Argüello | C18: =IF(H18="","",I18/IF(M18="",K18,M18)) -> 0.69565217 | D18: =IF(H18="","",J18/IF(M18="",K18,M18)) -> 0.26086957 | E18: =IF(H18="","",K18/IF(M18="",K18,M18)) -> 0.043478261 | G18: =IFERROR(VLOOKUP(H18,Datos!C:D,2,0),"") -> Centro | H18: Yuriana Argüello | I18: 16 | J18: 6 | K18: 1 | L18: 23 | M18: =IF(H18="","",IF(L18="",K18,L18)) -> 23 | N18: =_xlfn.XLOOKUP(H18,Datos!$AT$3:$AT$30,Datos!$AX$3:$AX$30,"") -> 319335.24 | O18: =$N$4 -> 423867.48 | P18: =IF(AND(N18>=LARGE($N$4:$N$31,5),M18>=LARGE($M$4:$M$31,5)),1,0) -> 0
B19: =IF(H19="","",H19) -> Blanca Montoya | C19: =IF(H19="","",I19/IF(M19="",K19,M19)) -> 0.80952381 | D19: =IF(H19="","",J19/IF(M19="",K19,M19)) -> 0.095238095 | E19: =IF(H19="","",K19/IF(M19="",K19,M19)) -> 0.095238095 | G19: =IFERROR(VLOOKUP(H19,Datos!C:D,2,0),"") -> Centro | H19: Blanca Montoya | I19: 17 | J19: 2 | K19: 2 | L19: 21 | M19: =IF(H19="","",IF(L19="",K19,L19)) -> 21 | N19: =_xlfn.XLOOKUP(H19,Datos!$AT$3:$AT$30,Datos!$AX$3:$AX$30,"") -> 84231.08 | O19: =$N$4 -> 423867.48 | P19: =IF(AND(N19>=LARGE($N$4:$N$31,5),M19>=LARGE($M$4:$M$31,5)),1,0) -> 0
B20: =IF(H20="","",H20) -> Sandra Escoto | C20: =IF(H20="","",I20/IF(M20="",K20,M20)) -> 0.35 | D20: =IF(H20="","",J20/IF(M20="",K20,M20)) -> 0.2 | E20: =IF(H20="","",K20/IF(M20="",K20,M20)) -> 0.45 | G20: =IFERROR(VLOOKUP(H20,Datos!C:D,2,0),"") -> Centro | H20: Sandra Escoto | I20: 7 | J20: 4 | K20: 9 | L20: 20 | M20: =IF(H20="","",IF(L20="",K20,L20)) -> 20 | N20: =_xlfn.XLOOKUP(H20,Datos!$AT$3:$AT$30,Datos!$AX$3:$AX$30,"") -> 218030.12 | O20: =$N$4 -> 423867.48 | P20: =IF(AND(N20>=LARGE($N$4:$N$31,5),M20>=LARGE($M$4:$M$31,5)),1,0) -> 0
B21: =IF(H21="","",H21) -> Noemí Castillo | C21: =IF(H21="","",I21/IF(M21="",K21,M21)) -> 0.26315789 | D21: =IF(H21="","",J21/IF(M21="",K21,M21)) -> 0.36842105 | E21: =IF(H21="","",K21/IF(M21="",K21,M21)) -> 0.36842105 | G21: =IFERROR(VLOOKUP(H21,Datos!C:D,2,0),"") -> Norte | H21: Noemí Castillo | I21: 5 | J21: 7 | K21: 7 | L21: 19 | M21: =IF(H21="","",IF(L21="",K21,L21)) -> 19 | N21: =_xlfn.XLOOKUP(H21,Datos!$AT$3:$AT$30,Datos!$AX$3:$AX$30,"") -> 86697.24 | O21: =$N$4 -> 423867.48 | P21: =IF(AND(N21>=LARGE($N$4:$N$31,5),M21>=LARGE($M$4:$M$31,5)),1,0) -> 0
B22: =IF(H22="","",H22) -> Julio César Trejo | C22: =IF(H22="","",I22/IF(M22="",K22,M22)) -> 0.33333333 | D22: =IF(H22="","",J22/IF(M22="",K22,M22)) -> 0.22222222 | E22: =IF(H22="","",K22/IF(M22="",K22,M22)) -> 0.44444444 | G22: =IFERROR(VLOOKUP(H22,Datos!C:D,2,0),"") -> Norte | H22: Julio César Trejo | I22: 6 | J22: 4 | K22: 8 | L22: 18 | M22: =IF(H22="","",IF(L22="",K22,L22)) -> 18 | N22: =_xlfn.XLOOKUP(H22,Datos!$AT$3:$AT$30,Datos!$AX$3:$AX$30,"") -> 251318.64 | O22: =$N$4 -> 423867.48 | P22: =IF(AND(N22>=LARGE($N$4:$N$31,5),M22>=LARGE($M$4:$M$31,5)),1,0) -> 0
B23: =IF(H23="","",H23) -> Giovanni Salas | C23: =IF(H23="","",I23/IF(M23="",K23,M23)) -> 0.26666667 | D23: =IF(H23="","",J23/IF(M23="",K23,M23)) -> 0.4 | E23: =IF(H23="","",K23/IF(M23="",K23,M23)) -> 0.33333333 | G23: =IFERROR(VLOOKUP(H23,Datos!C:D,2,0),"") -> Norte | H23: Giovanni Salas | I23: 4 | J23: 6 | K23: 5 | L23: 15 | M23: =IF(H23="","",IF(L23="",K23,L23)) -> 15 | N23: =_xlfn.XLOOKUP(H23,Datos!$AT$3:$AT$30,Datos!$AX$3:$AX$30,"") -> 263328.12 | O23: =$N$4 -> 423867.48 | P23: =IF(AND(N23>=LARGE($N$4:$N$31,5),M23>=LARGE($M$4:$M$31,5)),1,0) -> 0
B24: =IF(H24="","",H24) -> Jose Carlos Orozco | C24: =IF(H24="","",I24/IF(M24="",K24,M24)) -> 0.21428571 | D24: =IF(H24="","",J24/IF(M24="",K24,M24)) -> 0.071428571 | E24: =IF(H24="","",K24/IF(M24="",K24,M24)) -> 0.71428571 | G24: =IFERROR(VLOOKUP(H24,Datos!C:D,2,0),"") -> Centro | H24: Jose Carlos Orozco | I24: 3 | J24: 1 | K24: 10 | L24: 14 | M24: =IF(H24="","",IF(L24="",K24,L24)) -> 14 | N24: =_xlfn.XLOOKUP(H24,Datos!$AT$3:$AT$30,Datos!$AX$3:$AX$30,"") -> 252958.88 | O24: =$N$4 -> 423867.48 | P24: =IF(AND(N24>=LARGE($N$4:$N$31,5),M24>=LARGE($M$4:$M$31,5)),1,0) -> 0
B25: =IF(H25="","",H25) -> Antonio Salazar | C25: =IF(H25="","",I25/IF(M25="",K25,M25)) -> 0.36363636 | D25: =IF(H25="","",J25/IF(M25="",K25,M25)) -> 0.54545455 | E25: =IF(H25="","",K25/IF(M25="",K25,M25)) -> 0.090909091 | G25: =IFERROR(VLOOKUP(H25,Datos!C:D,2,0),"") -> Norte | H25: Antonio Salazar | I25: 4 | J25: 6 | K25: 1 | L25: 11 | M25: =IF(H25="","",IF(L25="",K25,L25)) -> 11 | N25: =_xlfn.XLOOKUP(H25,Datos!$AT$3:$AT$30,Datos!$AX$3:$AX$30,"") -> 39933 | O25: =$N$4 -> 423867.48 | P25: =IF(AND(N25>=LARGE($N$4:$N$31,5),M25>=LARGE($M$4:$M$31,5)),1,0) -> 0
B26: =IF(H26="","",H26) -> Karla Ángeles | C26: =IF(H26="","",I26/IF(M26="",K26,M26)) -> 0.27272727 | D26: =IF(H26="","",J26/IF(M26="",K26,M26)) -> 0.45454545 | E26: =IF(H26="","",K26/IF(M26="",K26,M26)) -> 0.27272727 | G26: =IFERROR(VLOOKUP(H26,Datos!C:D,2,0),"") -> Centro | H26: Karla Ángeles | I26: 3 | J26: 5 | K26: 3 | L26: 11 | M26: =IF(H26="","",IF(L26="",K26,L26)) -> 11 | N26: =_xlfn.XLOOKUP(H26,Datos!$AT$3:$AT$30,Datos!$AX$3:$AX$30,"") -> 33425.4 | O26: =$N$4 -> 423867.48 | P26: =IF(AND(N26>=LARGE($N$4:$N$31,5),M26>=LARGE($M$4:$M$31,5)),1,0) -> 0
B27: =IF(H27="","",H27) -> Dulce González | C27: =IF(H27="","",I27/IF(M27="",K27,M27)) -> 0.5 | D27: =IF(H27="","",J27/IF(M27="",K27,M27)) -> 0.2 | E27: =IF(H27="","",K27/IF(M27="",K27,M27)) -> 0.3 | G27: =IFERROR(VLOOKUP(H27,Datos!C:D,2,0),"") -> Centro | H27: Dulce González | I27: 5 | J27: 2 | K27: 3 | L27: 10 | M27: =IF(H27="","",IF(L27="",K27,L27)) -> 10 | N27: =_xlfn.XLOOKUP(H27,Datos!$AT$3:$AT$30,Datos!$AX$3:$AX$30,"") -> 78962.209 | O27: =$N$4 -> 423867.48 | P27: =IF(AND(N27>=LARGE($N$4:$N$31,5),M27>=LARGE($M$4:$M$31,5)),1,0) -> 0
B28: =IF(H28="","",H28) -> Roger Gómez | C28: =IF(H28="","",I28/IF(M28="",K28,M28)) -> 0.14285714 | D28: =IF(H28="","",J28/IF(M28="",K28,M28)) -> 0.85714286 | E28: =IF(H28="","",K28/IF(M28="",K28,M28)) -> 0 | G28: =IFERROR(VLOOKUP(H28,Datos!C:D,2,0),"") -> Sur | H28: Roger Gómez | I28: 1 | J28: 6 | L28: 7 | M28: =IF(H28="","",IF(L28="",K28,L28)) -> 7 | N28: =_xlfn.XLOOKUP(H28,Datos!$AT$3:$AT$30,Datos!$AX$3:$AX$30,"") -> 14593.96 | O28: =$N$4 -> 423867.48 | P28: =IF(AND(N28>=LARGE($N$4:$N$31,5),M28>=LARGE($M$4:$M$31,5)),1,0) -> 0
B29: =IF(H29="","",H29) -> David Montañéz | C29: =IF(H29="","",I29/IF(M29="",K29,M29)) -> 0.33333333 | D29: =IF(H29="","",J29/IF(M29="",K29,M29)) -> 0.5 | E29: =IF(H29="","",K29/IF(M29="",K29,M29)) -> 0.16666667 | G29: =IFERROR(VLOOKUP(H29,Datos!C:D,2,0),"") -> Centro | H29: David Montañéz | I29: 2 | J29: 3 | K29: 1 | L29: 6 | M29: =IF(H29="","",IF(L29="",K29,L29)) -> 6 | N29: =_xlfn.XLOOKUP(H29,Datos!$AT$3:$AT$30,Datos!$AX$3:$AX$30,"") -> 16365.28 | O29: =$N$4 -> 423867.48 | P29: =IF(AND(N29>=LARGE($N$4:$N$31,5),M29>=LARGE($M$4:$M$31,5)),1,0) -> 0
B30: =IF(H30="","",H30) -> Noe Acevedo | C30: =IF(H30="","",I30/IF(M30="",K30,M30)) -> 0.4 | D30: =IF(H30="","",J30/IF(M30="",K30,M30)) -> 0.2 | E30: =IF(H30="","",K30/IF(M30="",K30,M30)) -> 0.4 | G30: =IFERROR(VLOOKUP(H30,Datos!C:D,2,0),"") -> Norte | H30: Noe Acevedo | I30: 2 | J30: 1 | K30: 2 | L30: 5 | M30: =IF(H30="","",IF(L30="",K30,L30)) -> 5 | N30: =_xlfn.XLOOKUP(H30,Datos!$AT$3:$AT$30,Datos!$AX$3:$AX$30,"") -> 117243.52 | O30: =$N$4 -> 423867.48 | P30: =IF(AND(N30>=LARGE($N$4:$N$31,5),M30>=LARGE($M$4:$M$31,5)),1,0) -> 0
B31: =IF(H31="","",H31) -> Antonio Hernández | C31: =IF(H31="","",I31/IF(M31="",K31,M31)) -> 1 | D31: =IF(H31="","",J31/IF(M31="",K31,M31)) -> 0 | E31: =IF(H31="","",K31/IF(M31="",K31,M31)) -> 0 | G31: =IFERROR(VLOOKUP(H31,Datos!C:D,2,0),"") -> Norte | H31: Antonio Hernández | I31: 4 | L31: 4 | M31: =IF(H31="","",IF(L31="",K31,L31)) -> 4 | N31: =_xlfn.XLOOKUP(H31,Datos!$AT$3:$AT$30,Datos!$AX$3:$AX$30,"") | O31: =$N$4 -> 423867.48 | P31: =IF(AND(N31>=LARGE($N$4:$N$31,5),M31>=LARGE($M$4:$M$31,5)),1,0) -> 0
B32: =IF(H32="","",H32) -> Carlos Guerra | C32: =IF(H32="","",I32/IF(M32="",K32,M32)) -> 0.25 | D32: =IF(H32="","",J32/IF(M32="",K32,M32)) -> 0.75 | E32: =IF(H32="","",K32/IF(M32="",K32,M32)) -> 0 | G32: =IFERROR(VLOOKUP(H32,Datos!C:D,2,0),"") -> Centro | H32: Carlos Guerra | I32: 1 | J32: 3 | L32: 4 | M32: =IF(H32="","",IF(L32="",K32,L32)) -> 4 | N32: =_xlfn.XLOOKUP(H32,Datos!$AT$3:$AT$30,Datos!$AX$3:$AX$30,"") -> 92933.4
H33: Alondra Díaz | I33: 1 | J33: 2 | L33: 3 | M33: =IF(H33="","",IF(L33="",K33,L33)) -> 3 | N33: =_xlfn.XLOOKUP(H33,Datos!$AT$3:$AT$30,Datos!$AX$3:$AX$30,"") -> 4796.6
H34: Carlos Díaz | I34: 2 | L34: 2 | M34: =IF(H34="","",IF(L34="",K34,L34)) -> 2 | N34: =_xlfn.XLOOKUP(H34,Datos!$AT$3:$AT$30,Datos!$AX$3:$AX$30,"")
H35: Margarita González | I35: 1 | L35: 1 | M35: =IF(H35="","",IF(L35="",K35,L35)) -> 1 | N35: =_xlfn.XLOOKUP(H35,Datos!$AT$3:$AT$30,Datos!$AX$3:$AX$30,"")

Sheet Datos
A1: Fecha de alta | B1: Mes | C1: Ejecutivo | D1: Región | E1: Núm. De cliente | F1: Categoría | G1: Estatus | H1: Meses facturados | I1: Enero | J1: Febrero | K1: Marzo | L1: Abril | M1: Mayo | N1: Junio | O1: Julio | P1: Agosto | Q1: Suma de ventas | R1: Saldo pdte. a junio | S1: Meses facturados | T1: Pagado a junio | U1: % de deuda | V1: Categoría | W1: Categoría de pago | X1: Saldo enero | Y1: Saldo febrero | Z1: Saldo marzo | AA1: Saldo abril | AB1: Saldo Mayo | AC1: Saldo Junio | AD1: Saldo Julio | AE1: Activo/ Inactivo | AQ1: EJECUTIVOS | AR1: REGIÓN | AT1: Suma de Suma de ventas | AU1: Categoría
A2: 44564 | B2: =PROPER(TEXT(A2,"mmmm")) -> Enero | C2: Miguel Romero | D2: =VLOOKUP(Datos!$C2,$AQ$2:$AR$41,2,0) -> Centro | E2: 23080 | F2: {=_xlfn.IFS(H2=0,"Alta sin facturar",H2>2,"Cliente",H2>0,"Cliente nuevo")} -> Alta sin facturar | H2: =COUNTIF(I2:P2,">0") -> 0 | I2: 0 | J2: 0 | K2: 0 | L2: 0 | M2: 0 | N2: 0 | O2: 0 | P2: 0 | Q2: =SUBTOTAL(109,I2:P2) -> 0 | S2: =COUNTIF(I2:P2,">0") -> 0 | T2: =Q2-R2 -> 0 | U2: =IF(Q2=0,0,R2/Q2) -> 0 | V2: {=_xlfn.IFS(S2=0,"Alta sin facturar",S2>2,"Cliente",S2>0,"Cliente nuevo")} -> Alta sin facturar | W2: =IF(T2<1,"Sin pago","Ha pagado") -> Sin pago | AG2: Ejecutivo | AH2: (Todas) | AQ2: Iván Luna | AR2: Norte | AT2: Ejecutivo | AU2: Alta sin facturar | AV2: Cliente nuevo | AW2: Cliente | AX2: Total general
A3: 44564 | B3: =PROPER(TEXT(A3,"mmmm")) -> Enero | C3: Sandra Escoto | D3: =VLOOKUP(Datos!$C3,$AQ$2:$AR$41,2,0) -> Centro | E3: 23081 | F3: {=_xlfn.IFS(H3=0,"Alta sin facturar",H3>2,"Cliente",H3>0,"Cliente nuevo")} -> Cliente | H3: =COUNTIF(I3:P3,">0") -> 8 | I3: 5336 | J3: 5744.32 | K3: 9239.4 | L3: 8745.24 | M3: 6961.16 | N3: 8067.8 | O3: 9052.64 | P3: 8302.12 | Q3: =SUBTOTAL(109,I3:P3) -> 61448.68 | R3: 228.52 | S3: =COUNTIF(I3:P3,">0") -> 8 | T3: =Q3-R3 -> 61220.16 | U3: =IF(Q3=0,0,R3/Q3) -> 0.0037188757 | V3: {=_xlfn.IFS(S3=0,"Alta sin facturar",S3>2,"Cliente",S3>0,"Cliente nuevo")} -> Cliente | W3: =IF(T3<1,"Sin pago","Ha pagado") -> Ha pagado | AQ3: Jesús Hernández | AR3: Centro | AT3: Antonio Salazar | AU3: 0 | AV3: 36884.52 | AW3: 3048.48 | AX3: 39933
A4: 44564 | B4: =PROPER(TEXT(A4,"mmmm")) -> Enero | C4: Sandra Escoto | D4: =VLOOKUP(Datos!$C4,$AQ$2:$AR$41,2,0) -> Centro | E4: 23082 | F4: {=_xlfn.IFS(H4=0,"Alta sin facturar",H4>2,"Cliente",H4>0,"Cliente nuevo")} -> Alta sin facturar | H4: =COUNTIF(I4:P4,">0") -> 0 | I4: 0 | J4: 0 | K4: 0 | L4: 0 | M4: 0 | N4: 0 | O4: 0 | P4: 0 | Q4: =SUBTOTAL(109,I4:P4) -> 0 | S4: =COUNTIF(I4:P4,">0") -> 0 | T4: =Q4-R4 -> 0 | U4: =IF(Q4=0,0,R4/Q4) -> 0 | V4: {=_xlfn.IFS(S4=0,"Alta sin facturar",S4>2,"Cliente",S4>0,"Cliente nuevo")} -> Alta sin facturar | W4: =IF(T4<1,"Sin pago","Ha pagado") -> Sin pago | AG4: Altas | AH4: Categoría | AQ4: PENDIENTE | AR4: Centro | AT4: Blanca Montoya | AU4: 0 | AV4: 27668.32 | AW4: 56562.76 | AX4: 84231.08
A5: 44565 | B5: =PROPER(TEXT(A5,"mmmm")) -> Enero | C5: Marcos López | D5: =VLOOKUP(Datos!$C5,$AQ$2:$AR$41,2,0) -> Sur | E5: 23083 | F5: {=_xlfn.IFS(H5=0,"Alta sin facturar",H5>2,"Cliente",H5>0,"Cliente nuevo")} -> Cliente nuevo | H5: =COUNTIF(I5:P5,">0") -> 2 | I5: 0 | J5: 0 | K5: 0 | L5: 0 | M5: 0 | N5: 690.2 | O5: 0 | P5: 1372.28 | Q5: =SUBTOTAL(109,I5:P5) -> 2062.48 | R5: 302.76 | S5: =COUNTIF(I5:P5,">0") -> 2 | T5: =Q5-R5 -> 1759.72 | U5: =IF(Q5=0,0,R5/Q5) -> 0.14679415 | V5: {=_xlfn.IFS(S5=0,"Alta sin facturar",S5>2,"Cliente",S5>0,"Cliente nuevo")} -> Cliente nuevo | W5: =IF(T5<1,"Sin pago","Ha pagado") -> Ha pagado | AG5: Mes | AH5: Alta sin facturar | AI5: Cliente | AJ5: Cliente nuevo | AK5: Total general | AQ5: Carlos Guerra | AR5: Centro | AT5: Cancelada | AU5: 0 | AX5: 0
A6: 44565 | B6: =PROPER(TEXT(A6,"mmmm")) -> Enero | C6: Yuriana Argüello | D6: =VLOOKUP(Datos!$C6,$AQ$2:$AR$41,2,0) -> Centro | E6: 23084 | F6: {=_xlfn.IFS(H6=0,"Alta sin facturar",H6>2,"Cliente",H6>0,"Cliente nuevo")} -> Cliente nuevo | H6: =COUNTIF(I6:P6,">0") -> 2 | I6: 0 | J6: 0 | K6: 0 | L6: 0 | M6: 0 | N6: 9320.6 | O6: 0 | P6: 221.56 | Q6: =SUBTOTAL(109,I6:P6) -> 9542.16 | R6: 324.8 | S6: =COUNTIF(I6:P6,">0") -> 2 | T6: =Q6-R6 -> 9217.36 | U6: =IF(Q6=0,0,R6/Q6) -> 0.034038415 | V6: {=_xlfn.IFS(S6=0,"Alta sin facturar",S6>2,"Cliente",S6>0,"Cliente nuevo")} -> Cliente nuevo | W6: =IF(T6<1,"Sin pago","Ha pagado") -> Ha pagado | AG6: Enero | AH6: 55 | AI6: 42 | AJ6: 35 | AK6: 132 | AQ6: Blanca Montoya | AR6: Centro | AT6: Christian Castellanos | AU6: 0 | AV6: 26464.24 | AW6: 809691.6 | AX6: 836155.84
A7: 44565 | B7: =PROPER(TEXT(A7,"mmmm")) -> Enero | C7: Yareli Flores | D7: =VLOOKUP(Datos!$C7,$AQ$2:$AR$41,2,0) -> Centro | E7: 23085 | F7: {=_xlfn.IFS(H7=0,"Alta sin facturar",H7>2,"Cliente",H7>0,"Cliente nuevo")} -> Alta sin facturar | H7: =COUNTIF(I7:P7,">0") -> 0 | I7: 0 | J7: 0 | K7: 0 | L7: 0 | M7: 0 | N7: 0 | O7: 0 | P7: 0 | Q7: =SUBTOTAL(109,I7:P7) -> 0 | R7: 8700 | S7: =COUNTIF(I7:P7,">0") -> 0 | T7: =Q7-R7 -> -8700 | U7: =IF(Q7=0,0,R7/Q7) -> 0 | V7: {=_xlfn.IFS(S7=0,"Alta sin facturar",S7>2,"Cliente",S7>0,"Cliente nuevo")} -> Alta sin facturar | W7: =IF(T7<1,"Sin pago","Ha pagado") -> Sin pago | AG7: Febrero | AH7: 28 | AI7: 28 | AJ7: 23 | AK7: 79 | AQ7: Yuriana Argüello | AR7: Centro | AT7: Diana Tejadilla | AU7: 0 | AV7: 21475.08 | AW7: 97147.68 | AX7: 118622.76
A8: 44567 | B8: =PROPER(TEXT(A8,"mmmm")) -> Enero | C8: Yuritzi Alejo | D8: =VLOOKUP(Datos!$C8,$AQ$2:$AR$41,2,0) -> Centro | E8: 23086 | F8: {=_xlfn.IFS(H8=0,"Alta sin facturar",H8>2,"Cliente",H8>0,"Cliente nuevo")} -> Cliente | H8: =COUNTIF(I8:P8,">0") -> 4 | I8: 2.32 | J8: 0 | K8: 0 | L8: 0 | M8: 290 | N8: 21460 | O8: 870 | P8: 0 | Q8: =SUBTOTAL(109,I8:P8) -> 22622.32 | R8: 3480 | S8: =COUNTIF(I8:P8,">0") -> 4 | T8: =Q8-R8 -> 19142.32 | U8: =IF(Q8=0,0,R8/Q8) -> 0.15383038 | V8: {=_xlfn.IFS(S8=0,"Alta sin facturar",S8>2,"Cliente",S8>0,"Cliente nuevo")} -> Cliente | W8: =IF(T8<1,"Sin pago","Ha pagado") -> Ha pagado | AG8: Marzo | AH8: 33 | AI8: 37 | AJ8: 24 | AK8: 94 | AQ8: Miguel Romero | AR8: Centro | AT8: Genaro Castro | AU8: 0 | AV8: 85880.6 | AW8: 295964.72 | AX8: 381845.32
A9: 44567 | B9: =PROPER(TEXT(A9,"mmmm")) -> Enero | C9: Yareli Flores | D9: =VLOOKUP(Datos!$C9,$AQ$2:$AR$41,2,0) -> Centro | E9: 23087 | F9: {=_xlfn.IFS(H9=0,"Alta sin facturar",H9>2,"Cliente",H9>0,"Cliente nuevo")} -> Cliente | H9: =COUNTIF(I9:P9,">0") -> 5 | I9: 1624 | J9: 0 | K9: 0 | L9: 870 | M9: 0 | N9: 5684 | O9: 870 | P9: 1392 | Q9: =SUBTOTAL(109,I9:P9) -> 10440 | R9: 2494 | S9: =COUNTIF(I9:P9,">0") -> 5 | T9: =Q9-R9 -> 7946 | U9: =IF(Q9=0,0,R9/Q9) -> 0.23888889 | V9: {=_xlfn.IFS(S9=0,"Alta sin facturar",S9>2,"Cliente",S9>0,"Cliente nuevo")} -> Cliente | W9: =IF(T9<1,"Sin pago","Ha pagado") -> Ha pagado | AG9: Abril | AH9: 18 | AI9: 36 | AJ9: 22 | AK9: 76 | AQ9: Dolores Jiménez | AR9: Norte | AT9: Giovanni Salas | AU9: 0 | AV9: 14687.92 | AW9: 248640.2 | AX9: 263328.12
A10: 44567 | B10: =PROPER(TEXT(A10,"mmmm")) -> Enero | C10: Genaro Castro | D10: =VLOOKUP(Datos!$C10,$AQ$2:$AR$41,2,0) -> Sur | E10: 23088 | F10: {=_xlfn.IFS(H10=0,"Alta sin facturar",H10>2,"Cliente",H10>0,"Cliente nuevo")} -> Alta sin facturar | H10: =COUNTIF(I10:P10,">0") -> 0 | I10: 0 | J10: 0 | K10: 0 | L10: 0 | M10: 0 | N10: 0 | O10: 0 | P10: 0 | Q10: =SUBTOTAL(109,I10:P10) -> 0 | S10: =COUNTIF(I10:P10,">0") -> 0 | T10: =Q10-R10 -> 0 | U10: =IF(Q10=0,0,R10/Q10) -> 0 | V10: {=_xlfn.IFS(S10=0,"Alta sin facturar",S10>2,"Cliente",S10>0,"Cliente nuevo")} -> Alta sin facturar | W10: =IF(T10<1,"Sin pago","Ha pagado") -> Sin pago | AG10: Mayo | AH10: 20 | AI10: 31 | AJ10: 26 | AK10: 77 | AQ10: Marcos López | AR10: Sur | AT10: Noe Acevedo | AU10: 0 | AV10: 5936.88 | AW10: 111306.64 | AX10: 117243.52
A11: 44567 | B11: =PROPER(TEXT(A11,"mmmm")) -> Enero | C11: Marcos López | D11: =VLOOKUP(Datos!$C11,$AQ$2:$AR$41,2,0) -> Sur | E11: 23089 | F11: {=_xlfn.IFS(H11=0,"Alta sin facturar",H11>2,"Cliente",H11>0,"Cliente nuevo")} -> Cliente nuevo | H11: =COUNTIF(I11:P11,">0") -> 2 | I11: 0 | J11: 0 | K11: 0 | L11: 0 | M11: 0 | N11: 2304.92 | O11: 0 | P11: 1083.44 | Q11: =SUBTOTAL(109,I11:P11) -> 3388.36 | R11: 428.04 | S11: =COUNTIF(I11:P11,">0") -> 2 | T11: =Q11-R11 -> 2960.32 | U11: =IF(Q11=0,0,R11/Q11) -> 0.1263266 | V11: {=_xlfn.IFS(S11=0,"Alta sin facturar",S11>2,"Cliente",S11>0,"Cliente nuevo")} -> Cliente nuevo | W11: =IF(T11<1,"Sin pago","Ha pagado") -> Ha pagado | AG11: Junio | AH11: 27 | AI11: 24 | AJ11: 50 | AK11: 101 | AQ11: Christian Castellanos | AR11: Norte | AT11: Oscar Moreno | AU11: 0 | AV11: 99958.36 | AX11: 99958.36
A12: 44567 | B12: =PROPER(TEXT(A12,"mmmm")) -> Enero | C12: Dulce González | D12: =VLOOKUP(Datos!$C12,$AQ$2:$AR$41,2,0) -> Centro | E12: 23090 | F12: {=_xlfn.IFS(H12=0,"Alta sin facturar",H12>2,"Cliente",H12>0,"Cliente nuevo")} -> Alta sin facturar | H12: =COUNTIF(I12:P12,">0") -> 0 | I12: 0 | J12: 0 | K12: 0 | L12: 0 | M12: 0 | N12: 0 | O12: 0 | P12: 0 | Q12: =SUBTOTAL(109,I12:P12) -> 0 | S12: =COUNTIF(I12:P12,">0") -> 0 | T12: =Q12-R12 -> 0 | U12: =IF(Q12=0,0,R12/Q12) -> 0 | V12: {=_xlfn.IFS(S12=0,"Alta sin facturar",S12>2,"Cliente",S12>0,"Cliente nuevo")} -> Alta sin facturar | W12: =IF(T12<1,"Sin pago","Ha pagado") -> Sin pago | AG12: Julio | AH12: 36 | AJ12: 56 | AK12: 92 | AQ12: Karla Ángeles | AR12: Centro | AT12: Ricardo Vidal | AU12: 0 | AV12: 69149.92 | AW12: 187642.76 | AX12: 256792.68
A13: 44567 | B13: =PROPER(TEXT(A13,"mmmm")) -> Enero | C13: Yareli Flores | D13: =VLOOKUP(Datos!$C13,$AQ$2:$AR$41,2,0) -> Centro | E13: 23091 | F13: {=_xlfn.IFS(H13=0,"Alta sin facturar",H13>2,"Cliente",H13>0,"Cliente nuevo")} -> Cliente | H13: =COUNTIF(I13:P13,">0") -> 3 | I13: 0 | J13: 0 | K13: 747.04 | L13: 174 | M13: 0 | N13: 1624 | O13: 0 | P13: 0 | Q13: =SUBTOTAL(109,I13:P13) -> 2545.04 | R13: 2371.04 | S13: =COUNTIF(I13:P13,">0") -> 3 | T13: =Q13-R13 -> 174 | U13: =IF(Q13=0,0,R13/Q13) -> 0.93163172 | V13: {=_xlfn.IFS(S13=0,"Alta sin facturar",S13>2,"Cliente",S13>0,"Cliente nuevo")} -> Cliente | W13: =IF(T13<1,"Sin pago","Ha pagado") -> Ha pagado | AG13: Agosto | AH13: 62 | AJ13: 13 | AK13: 75 | AQ13: David Montañéz | AR13: Centro | AT13: Sandra Escoto | AU13: 0 | AV13: 2702.8 | AW13: 215327.32 | AX13: 218030.12
A14: 44567 | B14: =PROPER(TEXT(A14,"mmmm")) -> Enero | C14: Iván Luna | D14: =VLOOKUP(Datos!$C14,$AQ$2:$AR$41,2,0) -> Norte | E14: 23092 | F14: {=_xlfn.IFS(H14=0,"Alta sin facturar",H14>2,"Cliente",H14>0,"Cliente nuevo")} -> Cliente | H14: =COUNTIF(I14:P14,">0") -> 8 | I14: 205253.88 | J14: 380995.04 | K14: 335546.24 | L14: 351265.4 | M14: 292277.08 | N14: 453933.52 | O14: 387232.36 | P14: 313720.84 | Q14: =SUBTOTAL(109,I14:P14) -> 2720224.4 | R14: 841165.88 | S14: =COUNTIF(I14:P14,">0") -> 8 | T14: =Q14-R14 -> 1879058.5 | U14: =IF(Q14=0,0,R14/Q14) -> 0.30922666 | V14: {=_xlfn.IFS(S14=0,"Alta sin facturar",S14>2,"Cliente",S14>0,"Cliente nuevo")} -> Cliente | W14: =IF(T14<1,"Sin pago","Ha pagado") -> Ha pagado | AG14: Total general | AH14: 279 | AI14: 198 | AJ14: 249 | AK14: 726 | AQ14: Diana Tejadilla | AR14: Centro | AT14: Yareli Flores | AU14: 0 | AV14: 49410.2 | AW14: 374457.28 | AX14: 423867.48
A15: 44567 | B15: =PROPER(TEXT(A15,"mmmm")) -> Enero | C15: Dolores Jiménez | D15: =VLOOKUP(Datos!$C15,$AQ$2:$AR$41,2,0) -> Norte | E15: 23093 | F15: {=_xlfn.IFS(H15=0,"Alta sin facturar",H15>2,"Cliente",H15>0,"Cliente nuevo")} -> Alta sin facturar | H15: =COUNTIF(I15:P15,">0") -> 0 | I15: 0 | J15: 0 | K15: 0 | L15: 0 | M15: 0 | N15: 0 | O15: 0 | P15: 0 | Q15: =SUBTOTAL(109,I15:P15) -> 0 | S15: =COUNTIF(I15:P15,">0") -> 0 | T15: =Q15-R15 -> 0 | U15: =IF(Q15=0,0,R15/Q15) -> 0 | V15: {=_xlfn.IFS(S15=0,"Alta sin facturar",S15>2,"Cliente",S15>0,"Cliente nuevo")} -> Alta sin facturar | W15: =IF(T15<1,"Sin pago","Ha pagado") -> Sin pago | AQ15: Noemí Castillo | AR15: Norte | AT15: Yuritzi Alejo | AU15: 0 | AV15: 12541.92 | AW15: 759737.94 | AX15: 772279.86
A16: 44568 | B16: =PROPER(TEXT(A16,"mmmm")) -> Enero | C16: Yuriana Argüello | D16: =VLOOKUP(Datos!$C16,$AQ$2:$AR$41,2,0) -> Centro | E16: 23094 | F16: {=_xlfn.IFS(H16=0,"Alta sin facturar",H16>2,"Cliente",H16>0,"Cliente nuevo")} -> Cliente | H16: =COUNTIF(I16:P16,">0") -> 3 | I16: 0 | J16: 0 | K16: 5800 | L16: 11600 | M16: 0 | N16: 262392 | O16: 0 | P16: 0 | Q16: =SUBTOTAL(109,I16:P16) -> 279792 | R16: 49590 | S16: =COUNTIF(I16:P16,">0") -> 3 | T16: =Q16-R16 -> 230202 | U16: =IF(Q16=0,0,R16/Q16) -> 0.17723881 | V16: {=_xlfn.IFS(S16=0,"Alta sin facturar",S16>2,"Cliente",S16>0,"Cliente nuevo")} -> Cliente | W16: =IF(T16<1,"Sin pago","Ha pagado") -> Ha pagado | AQ16: Oscar Moreno | AR16: Magallanes | AT16: Iván Luna | AU16: 0 | AV16: 70870.2 | AW16: 2877402 | AX16: 2948272.2
A17: 44568 | B17: =PROPER(TEXT(A17,"mmmm")) -> Enero | C17: Karla Ángeles | D17: =VLOOKUP(Datos!$C17,$AQ$2:$AR$41,2,0) -> Centro | E17: 23095 | F17: {=_xlfn.IFS(H17=0,"Alta sin facturar",H17>2,"Cliente",H17>0,"Cliente nuevo")} -> Cliente | H17: =COUNTIF(I17:P17,">0") -> 3 | I17: 534.76 | J17: 870 | K17: 0 | L17: 0 | M17: 0 | N17: 1102 | O17: 0 | P17: 0 | Q17: =SUBTOTAL(109,I17:P17) -> 2506.76 | R17: 1102 | S17: =COUNTIF(I17:P17,">0") -> 3 | T17: =Q17-R17 -> 1404.76 | U17: =IF(Q17=0,0,R17/Q17) -> 0.43961129 | V17: {=_xlfn.IFS(S17=0,"Alta sin facturar",S17>2,"Cliente",S17>0,"Cliente nuevo")} -> Cliente | W17: =IF(T17<1,"Sin pago","Ha pagado") -> Ha pagado | AG17: Ejecutivo | AH17: (Todas) | AQ17: Julio Trejo | AR17: Norte | AT17: Alfredo Almaráz | AU17: 0 | AV17: 104077.52 | AW17: 357601.32 | AX17: 461678.84
A18: 44569 | B18: =PROPER(TEXT(A18,"mmmm")) -> Enero | C18: Yuritzi Alejo | D18: =VLOOKUP(Datos!$C18,$AQ$2:$AR$41,2,0) -> Centro | E18: 23096 | F18: {=_xlfn.IFS(H18=0,"Alta sin facturar",H18>2,"Cliente",H18>0,"Cliente nuevo")} -> Alta sin facturar | H18: =COUNTIF(I18:P18,">0") -> 0 | I18: 0 | J18: 0 | K18: 0 | L18: 0 | M18: 0 | N18: 0 | O18: 0 | P18: 0 | Q18: =SUBTOTAL(109,I18:P18) -> 0 | R18: 928 | S18: =COUNTIF(I18:P18,">0") -> 0 | T18: =Q18-R18 -> -928 | U18: =IF(Q18=0,0,R18/Q18) -> 0 | V18: {=_xlfn.IFS(S18=0,"Alta sin facturar",S18>2,"Cliente",S18>0,"Cliente nuevo")} -> Alta sin facturar | W18: =IF(T18<1,"Sin pago","Ha pagado") -> Sin pago | AQ18: Genaro Castro | AR18: Sur | AT18: Noemí Castillo | AU18: 0 | AV18: 21712.88 | AW18: 64984.36 | AX18: 86697.24
A19: 44569 | B19: =PROPER(TEXT(A19,"mmmm")) -> Enero | C19: Alfredo Almaráz | D19: =VLOOKUP(Datos!$C19,$AQ$2:$AR$41,2,0) -> Magallanes | E19: 23097 | F19: {=_xlfn.IFS(H19=0,"Alta sin facturar",H19>2,"Cliente",H19>0,"Cliente nuevo")} -> Alta sin facturar | H19: =COUNTIF(I19:P19,">0") -> 0 | I19: 0 | J19: 0 | K19: 0 | L19: 0 | M19: 0 | N19: 0 | O19: 0 | P19: 0 | Q19: =SUBTOTAL(109,I19:P19) -> 0 | R19: 10211.48 | S19: =COUNTIF(I19:P19,">0") -> 0 | T19: =Q19-R19 -> -10211.48 | U19: =IF(Q19=0,0,R19/Q19) -> 0 | V19: {=_xlfn.IFS(S19=0,"Alta sin facturar",S19>2,"Cliente",S19>0,"Cliente nuevo")} -> Alta sin facturar | W19: =IF(T19<1,"Sin pago","Ha pagado") -> Sin pago | AG19: Suma de venta | AH19: Categoría | AQ19: Giovanni Salas | AR19: Norte | AT19: Marcos López | AU19: 0 | AV19: 312603.76 | AX19: 312603.76
A20: 44569 | B20: =PROPER(TEXT(A20,"mmmm")) -> Enero | C20: Alfredo Almaráz | D20: =VLOOKUP(Datos!$C20,$AQ$2:$AR$41,2,0) -> Magallanes | E20: 23098 | F20: {=_xlfn.IFS(H20=0,"Alta sin facturar",H20>2,"Cliente",H20>0,"Cliente nuevo")} -> Alta sin facturar | H20: =COUNTIF(I20:P20,">0") -> 0 | I20: 0 | J20: 0 | K20: 0 | L20: 0 | M20: 0 | N20: 0 | O20: 0 | P20: 0 | Q20: =SUBTOTAL(109,I20:P20) -> 0 | R20: 24.36 | S20: =COUNTIF(I20:P20,">0") -> 0 | T20: =Q20-R20 -> -24.36 | U20: =IF(Q20=0,0,R20/Q20) -> 0 | V20: {=_xlfn.IFS(S20=0,"Alta sin facturar",S20>2,"Cliente",S20>0,"Cliente nuevo")} -> Alta sin facturar | W20: =IF(T20<1,"Sin pago","Ha pagado") -> Sin pago | AG20: Mes | AH20: Alta sin facturar | AI20: Cliente | AJ20: Cliente nuevo | AK20: Total general | AQ20: Alfredo Orta | AR20: Centro | AT20: Dolores Jiménez | AU20: 0 | AV20: 12380.68 | AW20: 323878.96 | AX20: 336259.64
A21: 44569 | B21: =PROPER(TEXT(A21,"mmmm")) -> Enero | C21: Alfredo Almaráz | D21: =VLOOKUP(Datos!$C21,$AQ$2:$AR$41,2,0) -> Magallanes | E21: 23099 | F21: {=_xlfn.IFS(H21=0,"Alta sin facturar",H21>2,"Cliente",H21>0,"Cliente nuevo")} -> Cliente | H21: =COUNTIF(I21:P21,">0") -> 6 | I21: 0 | J21: 348 | K21: 0 | L21: 696 | M21: 116 | N21: 395.56 | O21: 627.56 | P21: 4127.28 | Q21: =SUBTOTAL(109,I21:P21) -> 6310.4 | R21: 696 | S21: =COUNTIF(I21:P21,">0") -> 6 | T21: =Q21-R21 -> 5614.4 | U21: =IF(Q21=0,0,R21/Q21) -> 0.11029412 | V21: {=_xlfn.IFS(S21=0,"Alta sin facturar",S21>2,"Cliente",S21>0,"Cliente nuevo")} -> Cliente | W21: =IF(T21<1,"Sin pago","Ha pagado") -> Ha pagado | AG21: Enero | AH21: 0 | AI21: 4216487.5 | AJ21: 239243.04 | AK21: 4455730.5 | AQ21: Ricardo Vidal | AR21: Magallanes | AT21: Julio César Trejo | AU21: 0 | AV21: 15404.8 | AW21: 235913.84 | AX21: 251318.64
A22: 44571 | B22: =PROPER(TEXT(A22,"mmmm")) -> Enero | C22: Yuritzi Alejo | D22: =VLOOKUP(Datos!$C22,$AQ$2:$AR$41,2,0) -> Centro | E22: 23100 | F22: {=_xlfn.IFS(H22=0,"Alta sin facturar",H22>2,"Cliente",H22>0,"Cliente nuevo")} -> Alta sin facturar | H22: =COUNTIF(I22:P22,">0") -> 0 | I22: 0 | J22: 0 | K22: 0 | L22: 0 | M22: 0 | N22: 0 | O22: 0 | P22: 0 | Q22: =SUBTOTAL(109,I22:P22) -> 0 | S22: =COUNTIF(I22:P22,">0") -> 0 | T22: =Q22-R22 -> 0 | U22: =IF(Q22=0,0,R22/Q22) -> 0 | V22: {=_xlfn.IFS(S22=0,"Alta sin facturar",S22>2,"Cliente",S22>0,"Cliente nuevo")} -> Alta sin facturar | W22: =IF(T22<1,"Sin pago","Ha pagado") -> Sin pago | AG22: Febrero | AH22: 0 | AI22: 923884.32 | AJ22: 139022.52 | AK22: 1062906.8 | AQ22: Rubí Rodríguez | AR22: Centro | AT22: Karla Ángeles | AU22: 0 | AV22: 19062.28 | AW22: 14363.12 | AX22: 33425.4
A23: 44571 | B23: =PROPER(TEXT(A23,"mmmm")) -> Enero | C23: Yuritzi Alejo | D23: =VLOOKUP(Datos!$C23,$AQ$2:$AR$41,2,0) -> Centro | E23: 23101 | F23: {=_xlfn.IFS(H23=0,"Alta sin facturar",H23>2,"Cliente",H23>0,"Cliente nuevo")} -> Alta sin facturar | H23: =COUNTIF(I23:P23,">0") -> 0 | I23: 0 | J23: 0 | K23: 0 | L23: 0 | M23: 0 | N23: 0 | O23: 0 | P23: 0 | Q23: =SUBTOTAL(109,I23:P23) -> 0 | R23: 0 | S23: =COUNTIF(I23:P23,">0") -> 0 | T23: =Q23-R23 -> 0 | U23: =IF(Q23=0,0,R23/Q23) -> 0 | V23: {=_xlfn.IFS(S23=0,"Alta sin facturar",S23>2,"Cliente",S23>0,"Cliente nuevo")} -> Alta sin facturar | W23: =IF(T23<1,"Sin pago","Ha pagado") -> Sin pago | AG23: Marzo | AH23: 0 | AI23: 964667.6 | AJ23: 98967.72 | AK23: 1063635.3 | AQ23: Antonio Hernández | AR23: Norte | AT23: Dulce González | AU23: 0 | AV23: 29568.249 | AW23: 49393.96 | AX23: 78962.209
A24: 44571 | B24: =PROPER(TEXT(A24,"mmmm")) -> Enero | C24: Sandra Escoto | D24: =VLOOKUP(Datos!$C24,$AQ$2:$AR$41,2,0) -> Centro | E24: 23102 | F24: {=_xlfn.IFS(H24=0,"Alta sin facturar",H24>2,"Cliente",H24>0,"Cliente nuevo")} -> Cliente | H24: =COUNTIF(I24:P24,">0") -> 7 | I24: 725 | J24: 0 | K24: 3528.72 | L24: 5274.52 | M24: 2395.4 | N24: 1633.28 | O24: 5761.72 | P24: 7464.6 | Q24: =SUBTOTAL(109,I24:P24) -> 26783.24 | R24: 0 | S24: =COUNTIF(I24:P24,">0") -> 7 | T24: =Q24-R24 -> 26783.24 | U24: =IF(Q24=0,0,R24/Q24) -> 0 | V24: {=_xlfn.IFS(S24=0,"Alta sin facturar",S24>2,"Cliente",S24>0,"Cliente nuevo")} -> Cliente | W24: =IF(T24<1,"Sin pago","Ha pagado") -> Ha pagado | AG24: Abril | AH24: 0 | AI24: 1000965.7 | AJ24: 43425.609 | AK24: 1044391.3 | AQ24: Dulce González | AR24: Centro | AT24: Jose Carlos Orozco | AU24: 0 | AV24: 81.2 | AW24: 252877.68 | AX24: 252958.88
A25: 44571 | B25: =PROPER(TEXT(A25,"mmmm")) -> Enero | C25: Sandra Escoto | D25: =VLOOKUP(Datos!$C25,$AQ$2:$AR$41,2,0) -> Centro | E25: 23103 | F25: {=_xlfn.IFS(H25=0,"Alta sin facturar",H25>2,"Cliente",H25>0,"Cliente nuevo")} -> Cliente | H25: =COUNTIF(I25:P25,">0") -> 4 | I25: 0 | J25: 0 | K25: 812 | L25: 0 | M25: 0 | N25: 9686 | O25: 1740 | P25: 1740 | Q25: =SUBTOTAL(109,I25:P25) -> 13978 | R25: 0 | S25: =COUNTIF(I25:P25,">0") -> 4 | T25: =Q25-R25 -> 13978 | U25: =IF(Q25=0,0,R25/Q25) -> 0 | V25: {=_xlfn.IFS(S25=0,"Alta sin facturar",S25>2,"Cliente",S25>0,"Cliente nuevo")} -> Cliente | W25: =IF(T25<1,"Sin pago","Ha pagado") -> Ha pagado | AG25: Mayo | AH25: 0 | AI25: 523948.8 | AJ25: 285948.12 | AK25: 809896.92 | AQ25: Magallanes | AR25: Magallanes | AT25: Carlos Guerra | AU25: 0 | AV25: 92933.4 | AX25: 92933.4
A26: 44571 | B26: =PROPER(TEXT(A26,"mmmm")) -> Enero | C26: Dolores Jiménez | D26: =VLOOKUP(Datos!$C26,$AQ$2:$AR$41,2,0) -> Norte | E26: 23104 | F26: {=_xlfn.IFS(H26=0,"Alta sin facturar",H26>2,"Cliente",H26>0,"Cliente nuevo")} -> Cliente | H26: =COUNTIF(I26:P26,">0") -> 6 | I26: 0 | J26: 1252.8 | K26: 0 | L26: 3949.8 | M26: 7078.32 | N26: 3289.76 | O26: 2485.88 | P26: 3384.88 | Q26: =SUBTOTAL(109,I26:P26) -> 21441.44 | R26: 0 | S26: =COUNTIF(I26:P26,">0") -> 6 | T26: =Q26-R26 -> 21441.44 | U26: =IF(Q26=0,0,R26/Q26) -> 0 | V26: {=_xlfn.IFS(S26=0,"Alta sin facturar",S26>2,"Cliente",S26>0,"Cliente nuevo")} -> Cliente | W26: =IF(T26<1,"Sin pago","Ha pagado") -> Ha pagado | AG26: Junio | AH26: 0 | AI26: 422584.52 | AJ26: 231706.52 | AK26: 654291.04 | AQ26: Antonio Salazar | AR26: Norte | AT26: Yuriana Argüello | AU26: 0 | AV26: 39543.24 | AW26: 279792 | AX26: 319335.24
A27: 44572 | B27: =PROPER(TEXT(A27,"mmmm")) -> Enero | C27: Rubí Rodríguez | D27: =VLOOKUP(Datos!$C27,$AQ$2:$AR$41,2,0) -> Centro | E27: 23105 | F27: {=_xlfn.IFS(H27=0,"Alta sin facturar",H27>2,"Cliente",H27>0,"Cliente nuevo")} -> Cliente nuevo | H27: =COUNTIF(I27:P27,">0") -> 2 | I27: 0 | J27: 0 | K27: 0 | L27: 580 | M27: 0 | N27: 580 | O27: 0 | P27: 0 | Q27: =SUBTOTAL(109,I27:P27) -> 1160 | R27: 0 | S27: =COUNTIF(I27:P27,">0") -> 2 | T27: =Q27-R27 -> 1160 | U27: =IF(Q27=0,0,R27/Q27) -> 0 | V27: {=_xlfn.IFS(S27=0,"Alta sin facturar",S27>2,"Cliente",S27>0,"Cliente nuevo")} -> Cliente nuevo | W27: =IF(T27<1,"Sin pago","Ha pagado") -> Ha pagado | AG27: Julio | AH27: 0 | AJ27: 251399.84 | AK27: 251399.84 | AQ27: Telemarketing | AR27: Norte | AT27: Alondra Díaz | AU27: 0 | AV27: 4796.6 | AX27: 4796.6
A28: 44572 | B28: =PROPER(TEXT(A28,"mmmm")) -> Enero | C28: Yuritzi Alejo | D28: =VLOOKUP(Datos!$C28,$AQ$2:$AR$41,2,0) -> Centro | E28: 23106 | F28: {=_xlfn.IFS(H28=0,"Alta sin facturar",H28>2,"Cliente",H28>0,"Cliente nuevo")} -> Alta sin facturar | H28: =COUNTIF(I28:P28,">0") -> 0 | I28: 0 | J28: 0 | K28: 0 | L28: 0 | M28: 0 | N28: 0 | O28: 0 | P28: 0 | Q28: =SUBTOTAL(109,I28:P28) -> 0 | S28: =COUNTIF(I28:P28,">0") -> 0 | T28: =Q28-R28 -> 0 | U28: =IF(Q28=0,0,R28/Q28) -> 0 | V28: {=_xlfn.IFS(S28=0,"Alta sin facturar",S28>2,"Cliente",S28>0,"Cliente nuevo")} -> Alta sin facturar | W28: =IF(T28<1,"Sin pago","Ha pagado") -> Sin pago | AG28: Agosto | AH28: 0 | AJ28: 24922.6 | AK28: 24922.6 | AQ28: Leonard Lule | AR28: Sur | AT28: David Montañéz | AU28: 0 | AV28: 10832.08 | AW28: 5533.2 | AX28: 16365.28
A29: 44572 | B29: =PROPER(TEXT(A29,"mmmm")) -> Enero | C29: Christian Castellanos | D29: =VLOOKUP(Datos!$C29,$AQ$2:$AR$41,2,0) -> Norte | E29: 23107 | F29: {=_xlfn.IFS(H29=0,"Alta sin facturar",H29>2,"Cliente",H29>0,"Cliente nuevo")} -> Cliente | H29: =COUNTIF(I29:P29,">0") -> 8 | I29: 34333.68 | J29: 22338.12 | K29: 34126.04 | L29: 26899.24 | M29: 17278.2 | N29: 46328.08 | O29: 24364.64 | P29: 22100.32 | Q29: =SUBTOTAL(109,I29:P29) -> 227768.32 | R29: 15179.76 | S29: =COUNTIF(I29:P29,">0") -> 8 | T29: =Q29-R29 -> 212588.56 | U29: =IF(Q29=0,0,R29/Q29) -> 0.066645616 | V29: {=_xlfn.IFS(S29=0,"Alta sin facturar",S29>2,"Cliente",S29>0,"Cliente nuevo")} -> Cliente | W29: =IF(T29<1,"Sin pago","Ha pagado") -> Ha pagado | AG29: Total general | AH29: 0 | AI29: 8052538.5 | AJ29: 1314636 | AK29: 9367174.4 | AQ29: Alfredo Almaráz | AR29: Magallanes | AT29: Roger Gómez | AU29: 0 | AV29: 14593.96 | AX29: 14593.96
A30: 44572 | B30: =PROPER(TEXT(A30,"mmmm")) -> Enero | C30: Yuritzi Alejo | D30: =VLOOKUP(Datos!$C30,$AQ$2:$AR$41,2,0) -> Centro | E30: 23108 | F30: {=_xlfn.IFS(H30=0,"Alta sin facturar",H30>2,"Cliente",H30>0,"Cliente nuevo")} -> Cliente | H30: =COUNTIF(I30:P30,">0") -> 7 | I30: 0 | J30: 2148.32 | K30: 1717.96 | L30: 909.44 | M30: 1039.36 | N30: 6173.52 | O30: 1209.88 | P30: 2263.16 | Q30: =SUBTOTAL(109,I30:P30) -> 15461.64 | R30: 0 | S30: =COUNTIF(I30:P30,">0") -> 7 | T30: =Q30-R30 -> 15461.64 | U30: =IF(Q30=0,0,R30/Q30) -> 0 | V30: {=_xlfn.IFS(S30=0,"Alta sin facturar",S30>2,"Cliente",S30>0,"Cliente nuevo")} -> Cliente | W30: =IF(T30<1,"Sin pago","Ha pagado") -> Ha pagado | AQ30: Yareli Flores | AR30: Centro | AT30: Rubí Rodríguez | AU30: 0 | AV30: 37791.64 | AW30: 181559.72 | AX30: 219351.36
A31: 44573 | B31: =PROPER(TEXT(A31,"mmmm")) -> Enero | C31: Marcos López | D31: =VLOOKUP(Datos!$C31,$AQ$2:$AR$41,2,0) -> Sur | E31: 23109 | F31: {=_xlfn.IFS(H31=0,"Alta sin facturar",H31>2,"Cliente",H31>0,"Cliente nuevo")} -> Cliente nuevo | H31: =COUNTIF(I31:P31,">0") -> 2 | I31: 0 | J31: 0 | K31: 0 | L31: 0 | M31: 0 | N31: 546.36 | O31: 0 | P31: 222.72 | Q31: =SUBTOTAL(109,I31:P31) -> 769.08 | R31: 291.16 | S31: =COUNTIF(I31:P31,">0") -> 2 | T31: =Q31-R31 -> 477.92 | U31: =IF(Q31=0,0,R31/Q31) -> 0.3785822 | V31: {=_xlfn.IFS(S31=0,"Alta sin facturar",S31>2,"Cliente",S31>0,"Cliente nuevo")} -> Cliente nuevo | W31: =IF(T31<1,"Sin pago","Ha pagado") -> Ha pagado | AG31: Categoría de pago | AH31: Ha pagado | AQ31: BEST | AR31: Centro | AT31: Miguel Romero | AU31: 0 | AV31: 36221 | AW31: 76814.04 | AX31: 113035.04
A32: 44573 | B32: =PROPER(TEXT(A32,"mmmm")) -> Enero | C32: Jose Carlos Orozco | D32: =VLOOKUP(Datos!$C32,$AQ$2:$AR$41,2,0) -> Centro | E32: 23110 | F32: {=_xlfn.IFS(H32=0,"Alta sin facturar",H32>2,"Cliente",H32>0,"Cliente nuevo")} -> Cliente | H32: =COUNTIF(I32:P32,">0") -> 6 | I32: 487.2 | J32: 629.88 | K32: 1485.96 | L32: 435 | M32: 403.68 | N32: 351.48 | O32: 0 | P32: 0 | Q32: =SUBTOTAL(109,I32:P32) -> 3793.2 | R32: 857.24 | S32: =COUNTIF(I32:P32,">0") -> 6 | T32: =Q32-R32 -> 2935.96 | U32: =IF(Q32=0,0,R32/Q32) -> 0.22599388 | V32: {=_xlfn.IFS(S32=0,"Alta sin facturar",S32>2,"Cliente",S32>0,"Cliente nuevo")} -> Cliente | W32: =IF(T32<1,"Sin pago","Ha pagado") -> Ha pagado | AG32: Ejecutivo | AH32: (Todas) | AQ32: Róger Gómez | AR32: Sur | AT32: Leonard Lule | AU32: 0 | AV32: 39401.72 | AW32: 172896.84 | AX32: 212298.56
A33: 44573 | B33: =PROPER(TEXT(A33,"mmmm")) -> Enero | C33: Rubí Rodríguez | D33: =VLOOKUP(Datos!$C33,$AQ$2:$AR$41,2,0) -> Centro | E33: 23111 | F33: {=_xlfn.IFS(H33=0,"Alta sin facturar",H33>2,"Cliente",H33>0,"Cliente nuevo")} -> Alta sin facturar | H33: =COUNTIF(I33:P33,">0") -> 0 | I33: 0 | J33: 0 | K33: 0 | L33: 0 | M33: 0 | N33: 0 | O33: 0 | P33: 0 | Q33: =SUBTOTAL(109,I33:P33) -> 0 | S33: =COUNTIF(I33:P33,">0") -> 0 | T33: =Q33-R33 -> 0 | U33: =IF(Q33=0,0,R33/Q33) -> 0 | V33: {=_xlfn.IFS(S33=0,"Alta sin facturar",S33>2,"Cliente",S33>0,"Cliente nuevo")} -> Alta sin facturar | W33: =IF(T33<1,"Sin pago","Ha pagado") -> Sin pago | AQ33: Margarita González | AR33: Norte | AT33: Margarita González | AU33: 0 | AX33: 0
A34: 44573 | B34: =PROPER(TEXT(A34,"mmmm")) -> Enero | C34: Yuriana Argüello | D34: =VLOOKUP(Datos!$C34,$AQ$2:$AR$41,2,0) -> Centro | E34: 23112 | F34: {=_xlfn.IFS(H34=0,"Alta sin facturar",H34>2,"Cliente",H34>0,"Cliente nuevo")} -> Alta sin facturar | H34: =COUNTIF(I34:P34,">0") -> 0 | I34: 0 | J34: 0 | K34: 0 | L34: 0 | M34: 0 | N34: 0 | O34: 0 | P34: 0 | Q34: =SUBTOTAL(109,I34:P34) -> 0 | S34: =COUNTIF(I34:P34,">0") -> 0 | T34: =Q34-R34 -> 0 | U34: =IF(Q34=0,0,R34/Q34) -> 0 | V34: {=_xlfn.IFS(S34=0,"Alta sin facturar",S34>2,"Cliente",S34>0,"Cliente nuevo")} -> Alta sin facturar | W34: =IF(T34<1,"Sin pago","Ha pagado") -> Sin pago | AG34: Cuenta de Núm. De cliente | AH34: Pago | AQ34: Carlos Díaz | AR34: Norte | AT34: Antonio Hernández | AU34: 0 | AX34: 0
A35: 44573 | B35: =PROPER(TEXT(A35,"mmmm")) -> Enero | C35: Yuriana Argüello | D35: =VLOOKUP(Datos!$C35,$AQ$2:$AR$41,2,0) -> Centro | E35: 23113 | F35: {=_xlfn.IFS(H35=0,"Alta sin facturar",H35>2,"Cliente",H35>0,"Cliente nuevo")} -> Alta sin facturar | H35: =COUNTIF(I35:P35,">0") -> 0 | I35: 0 | J35: 0 | K35: 0 | L35: 0 | M35: 0 | N35: 0 | O35: 0 | P35: 0 | Q35: =SUBTOTAL(109,I35:P35) -> 0 | S35: =COUNTIF(I35:P35,">0") -> 0 | T35: =Q35-R35 -> 0 | U35: =IF(Q35=0,0,R35/Q35) -> 0 | V35: {=_xlfn.IFS(S35=0,"Alta sin facturar",S35>2,"Cliente",S35>0,"Cliente nuevo")} -> Alta sin facturar | W35: =IF(T35<1,"Sin pago","Ha pagado") -> Sin pago | AG35: Categoría | AH35: Enero | AI35: Febrero | AJ35: Marzo | AK35: Abril | AL35: Mayo | AM35: Junio | AN35: Total general | AQ35: Jose Carlos Orozco | AR35: Centro | AT35: Carlos Díaz | AU35: 0 | AX35: 0
A36: 44573 | B36: =PROPER(TEXT(A36,"mmmm")) -> Enero | C36: Genaro Castro | D36: =VLOOKUP(Datos!$C36,$AQ$2:$AR$41,2,0) -> Sur | E36: 23114 | F36: {=_xlfn.IFS(H36=0,"Alta sin facturar",H36>2,"Cliente",H36>0,"Cliente nuevo")} -> Cliente nuevo | H36: =COUNTIF(I36:P36,">0") -> 2 | I36: 0 | J36: 0 | K36: 0 | L36: 0 | M36: 0 | N36: 91.64 | O36: 0 | P36: 366.56 | Q36: =SUBTOTAL(109,I36:P36) -> 458.2 | R36: 0 | S36: =COUNTIF(I36:P36,">0") -> 2 | T36: =Q36-R36 -> 458.2 | U36: =IF(Q36=0,0,R36/Q36) -> 0 | V36: {=_xlfn.IFS(S36=0,"Alta sin facturar",S36>2,"Cliente",S36>0,"Cliente nuevo")} -> Cliente nuevo | W36: =IF(T36<1,"Sin pago","Ha pagado") -> Ha pagado | AG36: Alta sin facturar | AH36: 13 | AI36: 14 | AJ36: 21 | AK36: 14 | AL36: 11 | AM36: 14 | AN36: 87 | AQ36: Sandra Escoto | AR36: Centro
A37: 44573 | B37: =PROPER(TEXT(A37,"mmmm")) -> Enero | C37: Rubí Rodríguez | D37: =VLOOKUP(Datos!$C37,$AQ$2:$AR$41,2,0) -> Centro | E37: 23115 | F37: {=_xlfn.IFS(H37=0,"Alta sin facturar",H37>2,"Cliente",H37>0,"Cliente nuevo")} -> Cliente nuevo | H37: =COUNTIF(I37:P37,">0") -> 1 | I37: 0 | J37: 0 | K37: 0 | L37: 3424.32 | M37: 0 | N37: 0 | O37: 0 | P37: 0 | Q37: =SUBTOTAL(109,I37:P37) -> 3424.32 | R37: 290 | S37: =COUNTIF(I37:P37,">0") -> 1 | T37: =Q37-R37 -> 3134.32 | U37: =IF(Q37=0,0,R37/Q37) -> 0.084688347 | V37: {=_xlfn.IFS(S37=0,"Alta sin facturar",S37>2,"Cliente",S37>0,"Cliente nuevo")} -> Cliente nuevo | W37: =IF(T37<1,"Sin pago","Ha pagado") -> Ha pagado | AG37: Cliente | AH37: 53 | AI37: 27 | AJ37: 33 | AK37: 25 | AL37: 10 | AM37: 0 | AN37: 148 | AQ37: Julio César Trejo | AR37: Norte
A38: 44573 | B38: =PROPER(TEXT(A38,"mmmm")) -> Enero | C38: Sandra Escoto | D38: =VLOOKUP(Datos!$C38,$AQ$2:$AR$41,2,0) -> Centro | E38: 23116 | F38: {=_xlfn.IFS(H38=0,"Alta sin facturar",H38>2,"Cliente",H38>0,"Cliente nuevo")} -> Cliente | H38: =COUNTIF(I38:P38,">0") -> 3 | I38: 276.08 | J38: 310.88 | K38: 926.84 | L38: 0 | M38: 0 | N38: 0 | O38: 0 | P38: 0 | Q38: =SUBTOTAL(109,I38:P38) -> 1513.8 | R38: 0 | S38: =COUNTIF(I38:P38,">0") -> 3 | T38: =Q38-R38 -> 1513.8 | U38: =IF(Q38=0,0,R38/Q38) -> 0 | V38: {=_xlfn.IFS(S38=0,"Alta sin facturar",S38>2,"Cliente",S38>0,"Cliente nuevo")} -> Cliente | W38: =IF(T38<1,"Sin pago","Ha pagado") -> Ha pagado | AG38: Cliente nuevo | AH38: 13 | AI38: 13 | AJ38: 8 | AK38: 17 | AL38: 29 | AM38: 49 | AN38: 129 | AQ38: Roger Gómez | AR38: Sur
A39: 44574 | B39: =PROPER(TEXT(A39,"mmmm")) -> Enero | C39: Ricardo Vidal | D39: =VLOOKUP(Datos!$C39,$AQ$2:$AR$41,2,0) -> Magallanes | E39: 23117 | F39: {=_xlfn.IFS(H39=0,"Alta sin facturar",H39>2,"Cliente",H39>0,"Cliente nuevo")} -> Cliente | H39: =COUNTIF(I39:P39,">0") -> 5 | I39: 0 | J39: 371.2 | K39: 0 | L39: 0 | M39: 280.72 | N39: 1968.52 | O39: 3811.76 | P39: 2569.4 | Q39: =SUBTOTAL(109,I39:P39) -> 9001.6 | R39: 1856 | S39: =COUNTIF(I39:P39,">0") -> 5 | T39: =Q39-R39 -> 7145.6 | U39: =IF(Q39=0,0,R39/Q39) -> 0.20618557 | V39: {=_xlfn.IFS(S39=0,"Alta sin facturar",S39>2,"Cliente",S39>0,"Cliente nuevo")} -> Cliente | W39: =IF(T39<1,"Sin pago","Ha pagado") -> Ha pagado | AG39: Total general | AH39: 79 | AI39: 54 | AJ39: 62 | AK39: 56 | AL39: 50 | AM39: 63 | AN39: 364 | AQ39: Noe Acevedo | AR39: Norte
A40: 44574 | B40: =PROPER(TEXT(A40,"mmmm")) -> Enero | C40: Yareli Flores | D40: =VLOOKUP(Datos!$C40,$AQ$2:$AR$41,2,0) -> Centro | E40: 23118 | F40: {=_xlfn.IFS(H40=0,"Alta sin facturar",H40>2,"Cliente",H40>0,"Cliente nuevo")} -> Cliente nuevo | H40: =COUNTIF(I40:P40,">0") -> 1 | I40: 0 | J40: 0 | K40: 0 | L40: 0 | M40: 0 | N40: 12992 | O40: 0 | P40: 0 | Q40: =SUBTOTAL(109,I40:P40) -> 12992 | R40: 0 | S40: =COUNTIF(I40:P40,">0") -> 1 | T40: =Q40-R40 -> 12992 | U40: =IF(Q40=0,0,R40/Q40) -> 0 | V40: {=_xlfn.IFS(S40=0,"Alta sin facturar",S40>2,"Cliente",S40>0,"Cliente nuevo")} -> Cliente nuevo | W40: =IF(T40<1,"Sin pago","Ha pagado") -> Ha pagado | AQ40: Alondra Díaz | AR40: Sur
...
